Traceback (most recent call last):
  File "/home/fukui/workspace/TravelModeEstimation/scripts/05_segmentation/01_segment_detection.py", line 3, in <module>
    from geopy.distance import geodesic
ModuleNotFoundError: No module named 'geopy'
Traceback (most recent call last):
  File "/home/fukui/workspace/TravelModeEstimation/scripts/05_segmentation/01_segment_detection.py", line 5, in <module>
    from haversine import haversine, Unit
ModuleNotFoundError: No module named 'haversine'
multiprocessing.pool.RemoteTraceback: 
"""
Traceback (most recent call last):
  File "/home/fukui/workspace/TravelModeEstimation/.venv/lib/python3.9/site-packages/pandas/core/indexes/base.py", line 3812, in get_loc
    return self._engine.get_loc(casted_key)
  File "pandas/_libs/index.pyx", line 167, in pandas._libs.index.IndexEngine.get_loc
  File "pandas/_libs/index.pyx", line 196, in pandas._libs.index.IndexEngine.get_loc
  File "pandas/_libs/hashtable_class_helper.pxi", line 7088, in pandas._libs.hashtable.PyObjectHashTable.get_item
  File "pandas/_libs/hashtable_class_helper.pxi", line 7096, in pandas._libs.hashtable.PyObjectHashTable.get_item
KeyError: 'time_diff_s'

The above exception was the direct cause of the following exception:

Traceback (most recent call last):
  File "/home/fukui/.pyenv/versions/3.9.16/lib/python3.9/multiprocessing/pool.py", line 125, in worker
    result = (True, func(*args, **kwds))
  File "/home/fukui/.pyenv/versions/3.9.16/lib/python3.9/multiprocessing/pool.py", line 48, in mapstar
    return list(map(*args))
  File "/home/fukui/workspace/TravelModeEstimation/scripts/05_segmentation/01_segment_detection.py", line 66, in _process_task
    df = process_all_segments(df, v_thd, a_thd, dist_thd1, dist_thd2, limit_thd)
  File "/home/fukui/workspace/TravelModeEstimation/scripts/src/segmentation_func.py", line 190, in process_all_segments
    move_points = segment_by_label(group, v_thd, a_thd)
  File "/home/fukui/workspace/TravelModeEstimation/scripts/src/segmentation_func.py", line 27, in segment_by_label
    df = df.sort_values('datetime')\
  File "/home/fukui/workspace/TravelModeEstimation/.venv/lib/python3.9/site-packages/pandas/core/frame.py", line 5246, in assign
    data[k] = com.apply_if_callable(v, data)
  File "/home/fukui/workspace/TravelModeEstimation/.venv/lib/python3.9/site-packages/pandas/core/common.py", line 384, in apply_if_callable
    return maybe_callable(obj, **kwargs)
  File "/home/fukui/workspace/TravelModeEstimation/scripts/src/segmentation_func.py", line 29, in <lambda>
    acceleration=lambda x: x['P_speed'].diff(1)/x['time_diff_s'],
  File "/home/fukui/workspace/TravelModeEstimation/.venv/lib/python3.9/site-packages/pandas/core/frame.py", line 4107, in __getitem__
    indexer = self.columns.get_loc(key)
  File "/home/fukui/workspace/TravelModeEstimation/.venv/lib/python3.9/site-packages/pandas/core/indexes/base.py", line 3819, in get_loc
    raise KeyError(key) from err
KeyError: 'time_diff_s'
"""

The above exception was the direct cause of the following exception:

Traceback (most recent call last):
  File "/home/fukui/workspace/TravelModeEstimation/scripts/05_segmentation/01_segment_detection.py", line 84, in <module>
    results = pool.map(
  File "/home/fukui/.pyenv/versions/3.9.16/lib/python3.9/multiprocessing/pool.py", line 364, in map
    return self._map_async(func, iterable, mapstar, chunksize).get()
  File "/home/fukui/.pyenv/versions/3.9.16/lib/python3.9/multiprocessing/pool.py", line 771, in get
    raise self._value
KeyError: 'time_diff_s'
